<?xml version='1.0'?>

<robot name="my_robot" xmlns:xacro="http://www.ros.org/wiki/xacro">

  <xacro:include filename="$(find my_robot)/urdf/my_robot.gazebo"/>

  <link name="robot_footprint"></link>

  <joint name="robot_footprint_joint" type="fixed">
    <origin xyz="0 0 0" rpy="0 0 0" />
    <parent link="robot_footprint"/>
    <child link="chassis" />
  </joint>

  <link name='chassis'>
    <pose>0 0 0.1 0 0 0</pose>

    <inertial>
      <mass value="1.0"/>
      <origin xyz="0.0 0 0" rpy=" 0 0 0"/>
      <inertia
          ixx="0.1" ixy="0" ixz="0"
          iyy="0.1" iyz="0"
          izz="0.1"
      />
    </inertial>

    <collision name='collision'>
      <origin xyz="0 0 0" rpy=" 0 0 0"/> 
      <geometry>
        <box size=".6 .4 .3"/>
      </geometry>
    </collision>

    <visual name='chassis_visual'>
      <origin xyz="0 0 0" rpy=" 0 0 0"/>
      <geometry>
        <box size=".6 .4 .3"/>
      </geometry>
    </visual>
  </link>

  <link name='skid_steer_1'>
    <inertial>
      <origin xyz="0 0 0" rpy="0 0 0"/>
      <mass value="1"/>
      <inertia
        ixx="0.1" ixy="0" ixz="0"
        iyy="0.1" iyz="0"
        izz="0.1"
      />
    </inertial>

    <collision name="skid_steer_1_collision">
      <origin xyz="0 0 0" rpy="0 0 0"/>
      <geometry>
        <box size="0.2 0.01 0.2"/>
      </geometry>
    </collision>

    <visual name="skid_steer_1_visual">
      <origin xyz="0 0 0" rpy="0 0 0"/>
      <geometry>
        <box size="0.2 0.01 0.2"/>
      </geometry>
    </visual>
  </link>

  <joint type="fixed" name="skid_steer_1_joint">
    <origin xyz="0.4 0.19 -0.09" rpy="0 0 0"/>
    <child link="skid_steer_1"/>
    <parent link="chassis"/>
    <axis xyz="0 0 0" rpy="0 0 0"/>
  </joint>

  <link name='skid_steer_2'>
    <inertial>
      <origin xyz="0 0 0" rpy="0 0 0"/>
      <mass value="1"/>
      <inertia
        ixx="0.1" ixy="0" ixz="0"
        iyy="0.1" iyz="0"
        izz="0.1"
      />
    </inertial>

    <collision name="skid_steer_2_collision">
      <origin xyz="0 0 0" rpy="0 0 0"/>
      <geometry>
        <box size="0.2 0.01 0.2"/>
      </geometry>
    </collision>

    <visual name="skid_steer_2_visual">
      <origin xyz="0 0 0" rpy="0 0 0"/>
      <geometry>
        <box size="0.2 0.01 0.2"/>
      </geometry>
    </visual>
  </link>

  <joint type="fixed" name="skid_steer_2_joint">
    <origin xyz="0.4 -0.19 -0.09" rpy="0 0 0"/>
    <child link="skid_steer_2"/>
    <parent link="chassis"/>
    <axis xyz="0 0 0" rpy="0 0 0"/>
  </joint>

  <link name='skid_steer_3'>
    <inertial>
      <origin xyz="0 0 0" rpy="0 0 0"/>
      <mass value="1"/>
      <inertia
        ixx="0.1" ixy="0" ixz="0"
        iyy="0.1" iyz="0"
        izz="0.1"
      />
    </inertial>

    <collision name="skid_steer_3_collision">
      <origin xyz="0 0 0" rpy="0 0 0"/>
      <geometry>
        <box size="0.2 0.39 0.01"/>
      </geometry>
    </collision>

    <visual name="skid_steer_3_visual">
      <origin xyz="0 0 0" rpy="0 0 0"/>
      <geometry>
        <box size="0.2 0.39 0.01"/>
      </geometry>
    </visual>
  </link>

  <joint type="fixed" name="skid_steer_3_joint">
    <origin xyz="0.4 0 -0.195" rpy="0 0 0"/>
    <child link="skid_steer_3"/>
    <parent link="chassis"/>
    <axis xyz="0 0 0" rpy="0 0 0"/>
  </joint>

  <link name='right_front_wheel'>
    <inertial>
      <origin xyz="0 0 0" rpy="0 1.57 1.57"/>
      <mass value="1"/>
      <inertia
        ixx="0.1" ixy="0" ixz="0"
        iyy="0.1" iyz="0"
        izz="0.1"
      />
    </inertial>

    <collision name="right_front_wheel_collision">
      <origin xyz="0 0 0" rpy="0 1.57 1.57"/>
      <geometry>
        <cylinder radius="0.1" length="0.05"/>
      </geometry>
    </collision>

    <visual name="right_front_wheel_visual">
      <origin xyz="0 0 0" rpy="0 1.57 1.57"/>
      <geometry>
        <cylinder radius="0.1" length="0.05"/>
      </geometry>
    </visual>
  </link>

  <joint type="continuous" name="right_front_wheel_hinge">
    <origin xyz="0.2 -0.25 -0.1" rpy="0 0 0"/>
    <child link="right_front_wheel"/>
    <parent link="chassis"/>
    <axis xyz="0 1 0" rpy="0 0 0"/>
    <limit effort="10000" velocity="1000"/>
    <dynamics damping="1.0" friction="1.0"/>
  </joint>

  <link name='left_front_wheel'>
    <inertial>
      <origin xyz="0 0 0" rpy="0 1.57 1.57"/>
      <mass value="1"/>
      <inertia
        ixx="0.1" ixy="0" ixz="0"
        iyy="0.1" iyz="0"
        izz="0.1"
      />
    </inertial>

    <collision name="left_front_wheel_collision">
      <origin xyz="0 0 0" rpy="0 1.57 1.57"/>
      <geometry>
        <cylinder radius="0.1" length="0.05"/>
      </geometry>
    </collision>

    <visual name="left_front_wheel_visual">
      <origin xyz="0 0 0" rpy="0 1.57 1.57"/>
      <geometry>
        <cylinder radius="0.1" length="0.05"/>
      </geometry>
    </visual>
  </link>

  <joint type="continuous" name="left_front_wheel_hinge">
    <origin xyz="0.2 0.25 -0.1" rpy="0 0 0"/>
    <child link="left_front_wheel"/>
    <parent link="chassis"/>
    <axis xyz="0 1 0" rpy="0 0 0"/>
    <limit effort="10000" velocity="1000"/>
    <dynamics damping="1.0" friction="1.0"/>
  </joint>

  <link name='right_rear_wheel'>
    <inertial>
      <origin xyz="0 0 0" rpy="0 1.57 1.57"/>
      <mass value="1"/>
      <inertia
        ixx="0.1" ixy="0" ixz="0"
        iyy="0.1" iyz="0"
        izz="0.1"
      />
    </inertial>

    <collision name="right_rear_wheel_collision">
      <origin xyz="0 0 0" rpy="0 1.57 1.57"/>
      <geometry>
        <cylinder radius="0.1" length="0.05"/>
      </geometry>
    </collision>

    <visual name="right_rear_wheel_visual">
      <origin xyz="0 0 0" rpy="0 1.57 1.57"/>
      <geometry>
        <cylinder radius="0.1" length="0.05"/>
      </geometry>
    </visual>
  </link>

  <joint type="continuous" name="right_rear_wheel_hinge">
    <origin xyz="-0.2 -0.25 -0.1" rpy="0 0 0"/>
    <child link="right_rear_wheel"/>
    <parent link="chassis"/>
    <axis xyz="0 1 0" rpy="0 0 0"/>
    <limit effort="10000" velocity="1000"/>
    <dynamics damping="1.0" friction="1.0"/>
  </joint>

  <link name='left_rear_wheel'>
    <inertial>
      <origin xyz="0 0 0" rpy="0 1.57 1.57"/>
      <mass value="1"/>
      <inertia
        ixx="0.1" ixy="0" ixz="0"
        iyy="0.1" iyz="0"
        izz="0.1"
      />
    </inertial>

    <collision name="left_rear_wheel_collision">
      <origin xyz="0 0 0" rpy="0 1.57 1.57"/>
      <geometry>
        <cylinder radius="0.1" length="0.05"/>
      </geometry>
    </collision>

    <visual name="left_rear_wheel_visual">
      <origin xyz="0 0 0" rpy="0 1.57 1.57"/>
      <geometry>
        <cylinder radius="0.1" length="0.05"/>
      </geometry>
    </visual>
  </link>

  <joint type="continuous" name="left_rear_wheel_hinge">
    <origin xyz="-0.2 0.25 -0.1" rpy="0 0 0"/>
    <child link="left_rear_wheel"/>
    <parent link="chassis"/>
    <axis xyz="0 1 0" rpy="0 0 0"/>
    <limit effort="10000" velocity="1000"/>
    <dynamics damping="1.0" friction="1.0"/>
  </joint>

  <link name="camera">
    <inertial>
      <origin xyz="0 0 0" rpy="0 0 0"/>
      <mass value="0.1"/>
      <inertia
        ixx="1e-6" ixy="0" ixz="0"
        iyy="1e-6" iyz="0"
        izz="1e-6"
      />
    </inertial>

    <collision name="camera_collision">
      <origin xyz="0 0 0" rpy="0 0 0"/>
      <geometry>
        <box size="0.05 0.05 0.05"/>
      </geometry>
    </collision>

    <visual name="camera_visual">
      <origin xyz="0 0 0" rpy="0 0 0"/>
      <geometry>
        <box size="0.05 0.05 0.05"/>
      </geometry>
    </visual>
  </link>

  <joint type="fixed" name="camera_joint">
    <origin xyz="0.3 0 0.1" rpy="0 0 0"/>
    <child link="camera"/>
    <parent link="chassis"/>
    <axis xyz="0 1 0" rpy="0 0 0"/>
  </joint>

  <joint name="camera_optical_joint" type="fixed">
    <origin xyz="0 0 0" rpy="-1.5707 0 -1.5707"/>
    <parent link="camera"/>
    <child link="camera_link_optical"/>
  </joint>

  <link name="camera_link_optical">
  </link>

  <link name="hokuyo">
    <inertial>
      <origin xyz="0 0 0" rpy="0 0 0"/>
      <mass value="1e-5"/>
      <inertia
        ixx="1e-6" ixy="0" ixz="0"
        iyy="1e-6" iyz="0"
        izz="1e-6"
      />
    </inertial>

    <collision>
      <origin xyz="0 0 0" rpy="0 0 0"/>
      <geometry>
        <box size="0.1 0.1 0.1"/>
      </geometry>
    </collision>

    <visual>
      <origin xyz="0 0 0" rpy="0 0 0"/>
      <geometry>
        <mesh filename = "package://my_robot/meshes/hokuyo.dae"/>
      </geometry>
    </visual>
  </link>

  <joint type="fixed" name="hokuyo_joint">
    <origin xyz="0.25 0 0.2" rpy="0 0 0"/>
    <child link="hokuyo"/>
    <parent link="chassis"/>
    <axis xyz="0 1 0" rpy="0 0 0"/>
  </joint>

  <gazebo reference="left_front_wheel">
    <material>Gazebo/Yellow</material>
  </gazebo>

  <gazebo reference="right_front_wheel">
    <material>Gazebo/Yellow</material>
  </gazebo>

  <gazebo reference="left_rear_wheel">
    <material>Gazebo/Yellow</material>
  </gazebo>

  <gazebo reference="right_rear_wheel">
    <material>Gazebo/Yellow</material>
  </gazebo>

  <gazebo reference="chassis">
    <material>Gazebo/Grey</material>
  </gazebo>

  <!-- <gazebo reference="skid_steer_1">
    <material>Gazebo/Grey</material>
  </gazebo>

  <gazebo reference="skid_steer_2">
    <material>Gazebo/Grey</material>
  </gazebo>

  <gazebo reference="skid_steer_3">
    <material>Gazebo/Grey</material>
  </gazebo> -->

  <gazebo reference="camera">
    <material>Gazebo/Black</material>
  </gazebo>

</robot>
